{
 "cells": [
  {
   "cell_type": "code",
   "execution_count": 9,
   "metadata": {},
   "outputs": [],
   "source": [
    "from tensorflow import keras\n",
    "from keras.models import Sequential \n",
    "from keras.layers import Dense, Conv2D, Flatten, Dropout ,MaxPooling2D\n",
    "from keras.datasets import mnist\n",
    "from keras.utils import to_categorical "
   ]
  },
  {
   "cell_type": "code",
   "execution_count": 10,
   "metadata": {},
   "outputs": [],
   "source": [
    "import matplotlib.pyplot as plt\n",
    "import numpy as np "
   ]
  },
  {
   "cell_type": "code",
   "execution_count": 11,
   "metadata": {},
   "outputs": [],
   "source": [
    "(X_train, y_train), (X_test, y_test) = mnist.load_data()"
   ]
  },
  {
   "cell_type": "code",
   "execution_count": 15,
   "metadata": {},
   "outputs": [
    {
     "name": "stdout",
     "output_type": "stream",
     "text": [
      "(60000, 1, 28, 28)\n",
      "ERROR! Session/line number was not unique in database. History logging moved to new session 214\n",
      "(60000, 28, 28, 1)\n"
     ]
    }
   ],
   "source": [
    "print(X_train.shape)\n",
    "X_train = X_train.reshape(X_train.shape[0],  28, 28, 1).astype('float32')\n",
    "X_test = X_test.reshape(X_test.shape[0], 28, 28, 1).astype('float32')\n",
    "print(X_train.shape)\n",
    "X_train = X_train / 255\n",
    "X_test = X_test / 255\n",
    "y_train = to_categorical(y_train)\n",
    "y_test = to_categorical(y_test)\n",
    "num_classes = y_test.shape[1] \n",
    "# import keras.backend as K\n",
    "# K.set_image_dim_ordering('th')"
   ]
  },
  {
   "cell_type": "code",
   "execution_count": 16,
   "metadata": {},
   "outputs": [],
   "source": [
    "model = Sequential()\n",
    "model.add(Conv2D(32, (5, 5), input_shape=(28, 28, 1), activation='relu'))\n",
    "model.add(MaxPooling2D(pool_size=(2, 2)))\n",
    "model.add(Conv2D(16, (3, 3), activation='relu'))\n",
    "model.add(MaxPooling2D(pool_size=(2, 2)))\n",
    "model.add(Dropout(0.2))\n",
    "model.add(Flatten())\n",
    "model.add(Dense(128, activation='relu'))\n",
    "model.add(Dense(64, activation='relu'))\n",
    "model.add(Dense(num_classes, activation='softmax'))"
   ]
  },
  {
   "cell_type": "code",
   "execution_count": 17,
   "metadata": {},
   "outputs": [],
   "source": [
    "model.compile(optimizer='adam', loss='categorical_crossentropy', metrics = ['accuracy'])"
   ]
  },
  {
   "cell_type": "code",
   "execution_count": 18,
   "metadata": {},
   "outputs": [],
   "source": [
    "y_train_one_hot = to_categorical(y_train)\n",
    "y_test_one_hot =  to_categorical(y_test)\n"
   ]
  },
  {
   "cell_type": "code",
   "execution_count": null,
   "metadata": {},
   "outputs": [
    {
     "name": "stderr",
     "output_type": "stream",
     "text": [
      "ERROR:root:Internal Python error in the inspect module.\n",
      "Below is the traceback from this internal error.\n",
      "\n",
      "ERROR:root:Internal Python error in the inspect module.\n",
      "Below is the traceback from this internal error.\n",
      "\n",
      "ERROR:root:Internal Python error in the inspect module.\n",
      "Below is the traceback from this internal error.\n",
      "\n"
     ]
    },
    {
     "name": "stdout",
     "output_type": "stream",
     "text": [
      "Traceback (most recent call last):\n",
      "  File \"C:\\Users\\DELL\\AppData\\Roaming\\Python\\Python37\\site-packages\\IPython\\core\\interactiveshell.py\", line 3417, in run_code\n",
      "    exec(code_obj, self.user_global_ns, self.user_ns)\n",
      "  File \"<ipython-input-19-5d9448c728c7>\", line 1, in <module>\n",
      "    model.fit(X_train, y_train_one_hot, validation_data=(X_test, y_test_one_hot), epochs=5, verbose=1)\n",
      "  File \"C:\\Users\\DELL\\AppData\\Local\\Programs\\Python\\Python37\\lib\\site-packages\\keras\\engine\\training.py\", line 1154, in fit\n",
      "    batch_size=batch_size)\n",
      "  File \"C:\\Users\\DELL\\AppData\\Local\\Programs\\Python\\Python37\\lib\\site-packages\\keras\\engine\\training.py\", line 621, in _standardize_user_data\n",
      "    exception_prefix='target')\n",
      "  File \"C:\\Users\\DELL\\AppData\\Local\\Programs\\Python\\Python37\\lib\\site-packages\\keras\\engine\\training_utils.py\", line 135, in standardize_input_data\n",
      "    'with shape ' + str(data_shape))\n",
      "ValueError: Error when checking target: expected dense_3 to have 2 dimensions, but got array with shape (60000, 10, 2, 2, 2, 2, 2, 2)\n",
      "\n",
      "During handling of the above exception, another exception occurred:\n",
      "\n",
      "Traceback (most recent call last):\n",
      "  File \"C:\\Users\\DELL\\AppData\\Roaming\\Python\\Python37\\site-packages\\IPython\\core\\interactiveshell.py\", line 2044, in showtraceback\n",
      "    stb = value._render_traceback_()\n",
      "AttributeError: 'ValueError' object has no attribute '_render_traceback_'\n",
      "\n",
      "During handling of the above exception, another exception occurred:\n",
      "\n",
      "Traceback (most recent call last):\n",
      "  File \"C:\\Users\\DELL\\AppData\\Roaming\\Python\\Python37\\site-packages\\IPython\\core\\ultratb.py\", line 1169, in get_records\n",
      "    return _fixed_getinnerframes(etb, number_of_lines_of_context, tb_offset)\n",
      "  File \"C:\\Users\\DELL\\AppData\\Roaming\\Python\\Python37\\site-packages\\IPython\\core\\ultratb.py\", line 316, in wrapped\n",
      "    return f(*args, **kwargs)\n",
      "  File \"C:\\Users\\DELL\\AppData\\Roaming\\Python\\Python37\\site-packages\\IPython\\core\\ultratb.py\", line 350, in _fixed_getinnerframes\n",
      "    records = fix_frame_records_filenames(inspect.getinnerframes(etb, context))\n",
      "  File \"C:\\Users\\DELL\\AppData\\Local\\Programs\\Python\\Python37\\lib\\inspect.py\", line 1502, in getinnerframes\n",
      "    frameinfo = (tb.tb_frame,) + getframeinfo(tb, context)\n",
      "  File \"C:\\Users\\DELL\\AppData\\Local\\Programs\\Python\\Python37\\lib\\inspect.py\", line 1460, in getframeinfo\n",
      "    filename = getsourcefile(frame) or getfile(frame)\n",
      "  File \"C:\\Users\\DELL\\AppData\\Local\\Programs\\Python\\Python37\\lib\\inspect.py\", line 696, in getsourcefile\n",
      "    if getattr(getmodule(object, filename), '__loader__', None) is not None:\n",
      "  File \"C:\\Users\\DELL\\AppData\\Local\\Programs\\Python\\Python37\\lib\\inspect.py\", line 733, in getmodule\n",
      "    if ismodule(module) and hasattr(module, '__file__'):\n",
      "  File \"C:\\Users\\DELL\\AppData\\Local\\Programs\\Python\\Python37\\lib\\site-packages\\tensorflow\\__init__.py\", line 50, in __getattr__\n",
      "    module = self._load()\n",
      "  File \"C:\\Users\\DELL\\AppData\\Local\\Programs\\Python\\Python37\\lib\\site-packages\\tensorflow\\__init__.py\", line 44, in _load\n",
      "    module = _importlib.import_module(self.__name__)\n",
      "  File \"C:\\Users\\DELL\\AppData\\Local\\Programs\\Python\\Python37\\lib\\importlib\\__init__.py\", line 127, in import_module\n",
      "    return _bootstrap._gcd_import(name[level:], package, level)\n",
      "  File \"<frozen importlib._bootstrap>\", line 1006, in _gcd_import\n",
      "  File \"<frozen importlib._bootstrap>\", line 983, in _find_and_load\n",
      "  File \"<frozen importlib._bootstrap>\", line 965, in _find_and_load_unlocked\n",
      "ModuleNotFoundError: No module named 'tensorflow_core.estimator'\n",
      "Traceback (most recent call last):\n",
      "  File \"C:\\Users\\DELL\\AppData\\Roaming\\Python\\Python37\\site-packages\\IPython\\core\\interactiveshell.py\", line 3417, in run_code\n",
      "    exec(code_obj, self.user_global_ns, self.user_ns)\n",
      "  File \"<ipython-input-19-5d9448c728c7>\", line 1, in <module>\n",
      "    model.fit(X_train, y_train_one_hot, validation_data=(X_test, y_test_one_hot), epochs=5, verbose=1)\n",
      "  File \"C:\\Users\\DELL\\AppData\\Local\\Programs\\Python\\Python37\\lib\\site-packages\\keras\\engine\\training.py\", line 1154, in fit\n",
      "    batch_size=batch_size)\n",
      "  File \"C:\\Users\\DELL\\AppData\\Local\\Programs\\Python\\Python37\\lib\\site-packages\\keras\\engine\\training.py\", line 621, in _standardize_user_data\n",
      "    exception_prefix='target')\n",
      "  File \"C:\\Users\\DELL\\AppData\\Local\\Programs\\Python\\Python37\\lib\\site-packages\\keras\\engine\\training_utils.py\", line 135, in standardize_input_data\n",
      "    'with shape ' + str(data_shape))\n",
      "ValueError: Error when checking target: expected dense_3 to have 2 dimensions, but got array with shape (60000, 10, 2, 2, 2, 2, 2, 2)\n",
      "\n",
      "During handling of the above exception, another exception occurred:\n",
      "\n",
      "Traceback (most recent call last):\n",
      "  File \"C:\\Users\\DELL\\AppData\\Roaming\\Python\\Python37\\site-packages\\IPython\\core\\interactiveshell.py\", line 2044, in showtraceback\n",
      "    stb = value._render_traceback_()\n",
      "AttributeError: 'ValueError' object has no attribute '_render_traceback_'\n",
      "\n",
      "During handling of the above exception, another exception occurred:\n",
      "\n",
      "Traceback (most recent call last):\n",
      "  File \"C:\\Users\\DELL\\AppData\\Roaming\\Python\\Python37\\site-packages\\IPython\\core\\interactiveshell.py\", line 3337, in run_ast_nodes\n",
      "    if (await self.run_code(code, result,  async_=asy)):\n",
      "  File \"C:\\Users\\DELL\\AppData\\Roaming\\Python\\Python37\\site-packages\\IPython\\core\\interactiveshell.py\", line 3434, in run_code\n",
      "    self.showtraceback(running_compiled_code=True)\n",
      "  File \"C:\\Users\\DELL\\AppData\\Roaming\\Python\\Python37\\site-packages\\IPython\\core\\interactiveshell.py\", line 2047, in showtraceback\n",
      "    value, tb, tb_offset=tb_offset)\n",
      "  File \"C:\\Users\\DELL\\AppData\\Roaming\\Python\\Python37\\site-packages\\IPython\\core\\ultratb.py\", line 1436, in structured_traceback\n",
      "    self, etype, value, tb, tb_offset, number_of_lines_of_context)\n",
      "  File \"C:\\Users\\DELL\\AppData\\Roaming\\Python\\Python37\\site-packages\\IPython\\core\\ultratb.py\", line 1336, in structured_traceback\n",
      "    self, etype, value, tb, tb_offset, number_of_lines_of_context\n",
      "  File \"C:\\Users\\DELL\\AppData\\Roaming\\Python\\Python37\\site-packages\\IPython\\core\\ultratb.py\", line 1193, in structured_traceback\n",
      "    tb_offset)\n",
      "  File \"C:\\Users\\DELL\\AppData\\Roaming\\Python\\Python37\\site-packages\\IPython\\core\\ultratb.py\", line 1150, in format_exception_as_a_whole\n",
      "    last_unique, recursion_repeat = find_recursion(orig_etype, evalue, records)\n",
      "  File \"C:\\Users\\DELL\\AppData\\Roaming\\Python\\Python37\\site-packages\\IPython\\core\\ultratb.py\", line 451, in find_recursion\n",
      "    return len(records), 0\n",
      "TypeError: object of type 'NoneType' has no len()\n",
      "\n",
      "During handling of the above exception, another exception occurred:\n",
      "\n",
      "Traceback (most recent call last):\n",
      "  File \"C:\\Users\\DELL\\AppData\\Roaming\\Python\\Python37\\site-packages\\IPython\\core\\interactiveshell.py\", line 2044, in showtraceback\n",
      "    stb = value._render_traceback_()\n",
      "AttributeError: 'TypeError' object has no attribute '_render_traceback_'\n",
      "\n",
      "During handling of the above exception, another exception occurred:\n",
      "\n",
      "Traceback (most recent call last):\n",
      "  File \"C:\\Users\\DELL\\AppData\\Roaming\\Python\\Python37\\site-packages\\IPython\\core\\ultratb.py\", line 1169, in get_records\n",
      "    return _fixed_getinnerframes(etb, number_of_lines_of_context, tb_offset)\n",
      "  File \"C:\\Users\\DELL\\AppData\\Roaming\\Python\\Python37\\site-packages\\IPython\\core\\ultratb.py\", line 316, in wrapped\n",
      "    return f(*args, **kwargs)\n",
      "  File \"C:\\Users\\DELL\\AppData\\Roaming\\Python\\Python37\\site-packages\\IPython\\core\\ultratb.py\", line 350, in _fixed_getinnerframes\n",
      "    records = fix_frame_records_filenames(inspect.getinnerframes(etb, context))\n",
      "  File \"C:\\Users\\DELL\\AppData\\Local\\Programs\\Python\\Python37\\lib\\inspect.py\", line 1502, in getinnerframes\n",
      "    frameinfo = (tb.tb_frame,) + getframeinfo(tb, context)\n",
      "  File \"C:\\Users\\DELL\\AppData\\Local\\Programs\\Python\\Python37\\lib\\inspect.py\", line 1460, in getframeinfo\n",
      "    filename = getsourcefile(frame) or getfile(frame)\n",
      "  File \"C:\\Users\\DELL\\AppData\\Local\\Programs\\Python\\Python37\\lib\\inspect.py\", line 696, in getsourcefile\n",
      "    if getattr(getmodule(object, filename), '__loader__', None) is not None:\n",
      "  File \"C:\\Users\\DELL\\AppData\\Local\\Programs\\Python\\Python37\\lib\\inspect.py\", line 733, in getmodule\n",
      "    if ismodule(module) and hasattr(module, '__file__'):\n",
      "  File \"C:\\Users\\DELL\\AppData\\Local\\Programs\\Python\\Python37\\lib\\site-packages\\tensorflow\\__init__.py\", line 50, in __getattr__\n",
      "    module = self._load()\n",
      "  File \"C:\\Users\\DELL\\AppData\\Local\\Programs\\Python\\Python37\\lib\\site-packages\\tensorflow\\__init__.py\", line 44, in _load\n",
      "    module = _importlib.import_module(self.__name__)\n",
      "  File \"C:\\Users\\DELL\\AppData\\Local\\Programs\\Python\\Python37\\lib\\importlib\\__init__.py\", line 127, in import_module\n",
      "    return _bootstrap._gcd_import(name[level:], package, level)\n",
      "  File \"<frozen importlib._bootstrap>\", line 1006, in _gcd_import\n",
      "  File \"<frozen importlib._bootstrap>\", line 983, in _find_and_load\n",
      "  File \"<frozen importlib._bootstrap>\", line 965, in _find_and_load_unlocked\n",
      "ModuleNotFoundError: No module named 'tensorflow_core.estimator'\n",
      "Traceback (most recent call last):\n",
      "  File \"C:\\Users\\DELL\\AppData\\Roaming\\Python\\Python37\\site-packages\\IPython\\core\\interactiveshell.py\", line 3417, in run_code\n",
      "    exec(code_obj, self.user_global_ns, self.user_ns)\n",
      "  File \"<ipython-input-19-5d9448c728c7>\", line 1, in <module>\n",
      "    model.fit(X_train, y_train_one_hot, validation_data=(X_test, y_test_one_hot), epochs=5, verbose=1)\n",
      "  File \"C:\\Users\\DELL\\AppData\\Local\\Programs\\Python\\Python37\\lib\\site-packages\\keras\\engine\\training.py\", line 1154, in fit\n",
      "    batch_size=batch_size)\n",
      "  File \"C:\\Users\\DELL\\AppData\\Local\\Programs\\Python\\Python37\\lib\\site-packages\\keras\\engine\\training.py\", line 621, in _standardize_user_data\n",
      "    exception_prefix='target')\n",
      "  File \"C:\\Users\\DELL\\AppData\\Local\\Programs\\Python\\Python37\\lib\\site-packages\\keras\\engine\\training_utils.py\", line 135, in standardize_input_data\n",
      "    'with shape ' + str(data_shape))\n",
      "ValueError: Error when checking target: expected dense_3 to have 2 dimensions, but got array with shape (60000, 10, 2, 2, 2, 2, 2, 2)\n",
      "\n",
      "During handling of the above exception, another exception occurred:\n",
      "\n",
      "Traceback (most recent call last):\n",
      "  File \"C:\\Users\\DELL\\AppData\\Roaming\\Python\\Python37\\site-packages\\IPython\\core\\interactiveshell.py\", line 2044, in showtraceback\n",
      "    stb = value._render_traceback_()\n",
      "AttributeError: 'ValueError' object has no attribute '_render_traceback_'\n",
      "\n",
      "During handling of the above exception, another exception occurred:\n",
      "\n",
      "Traceback (most recent call last):\n",
      "  File \"C:\\Users\\DELL\\AppData\\Roaming\\Python\\Python37\\site-packages\\IPython\\core\\interactiveshell.py\", line 3337, in run_ast_nodes\n",
      "    if (await self.run_code(code, result,  async_=asy)):\n",
      "  File \"C:\\Users\\DELL\\AppData\\Roaming\\Python\\Python37\\site-packages\\IPython\\core\\interactiveshell.py\", line 3434, in run_code\n",
      "    self.showtraceback(running_compiled_code=True)\n",
      "  File \"C:\\Users\\DELL\\AppData\\Roaming\\Python\\Python37\\site-packages\\IPython\\core\\interactiveshell.py\", line 2047, in showtraceback\n",
      "    value, tb, tb_offset=tb_offset)\n",
      "  File \"C:\\Users\\DELL\\AppData\\Roaming\\Python\\Python37\\site-packages\\IPython\\core\\ultratb.py\", line 1436, in structured_traceback\n",
      "    self, etype, value, tb, tb_offset, number_of_lines_of_context)\n",
      "  File \"C:\\Users\\DELL\\AppData\\Roaming\\Python\\Python37\\site-packages\\IPython\\core\\ultratb.py\", line 1336, in structured_traceback\n",
      "    self, etype, value, tb, tb_offset, number_of_lines_of_context\n",
      "  File \"C:\\Users\\DELL\\AppData\\Roaming\\Python\\Python37\\site-packages\\IPython\\core\\ultratb.py\", line 1193, in structured_traceback\n",
      "    tb_offset)\n",
      "  File \"C:\\Users\\DELL\\AppData\\Roaming\\Python\\Python37\\site-packages\\IPython\\core\\ultratb.py\", line 1150, in format_exception_as_a_whole\n",
      "    last_unique, recursion_repeat = find_recursion(orig_etype, evalue, records)\n",
      "  File \"C:\\Users\\DELL\\AppData\\Roaming\\Python\\Python37\\site-packages\\IPython\\core\\ultratb.py\", line 451, in find_recursion\n",
      "    return len(records), 0\n",
      "TypeError: object of type 'NoneType' has no len()\n",
      "\n",
      "During handling of the above exception, another exception occurred:\n",
      "\n",
      "Traceback (most recent call last):\n",
      "  File \"C:\\Users\\DELL\\AppData\\Roaming\\Python\\Python37\\site-packages\\IPython\\core\\interactiveshell.py\", line 2044, in showtraceback\n",
      "    stb = value._render_traceback_()\n",
      "AttributeError: 'TypeError' object has no attribute '_render_traceback_'\n",
      "\n",
      "During handling of the above exception, another exception occurred:\n",
      "\n",
      "Traceback (most recent call last):\n",
      "  File \"C:\\Users\\DELL\\AppData\\Roaming\\Python\\Python37\\site-packages\\IPython\\core\\interactiveshell.py\", line 2922, in _run_cell\n",
      "    return runner(coro)\n",
      "  File \"C:\\Users\\DELL\\AppData\\Roaming\\Python\\Python37\\site-packages\\IPython\\core\\async_helpers.py\", line 68, in _pseudo_sync_runner\n",
      "    coro.send(None)\n",
      "  File \"C:\\Users\\DELL\\AppData\\Roaming\\Python\\Python37\\site-packages\\IPython\\core\\interactiveshell.py\", line 3146, in run_cell_async\n",
      "    interactivity=interactivity, compiler=compiler, result=result)\n",
      "  File \"C:\\Users\\DELL\\AppData\\Roaming\\Python\\Python37\\site-packages\\IPython\\core\\interactiveshell.py\", line 3356, in run_ast_nodes\n",
      "    self.showtraceback()\n",
      "  File \"C:\\Users\\DELL\\AppData\\Roaming\\Python\\Python37\\site-packages\\IPython\\core\\interactiveshell.py\", line 2047, in showtraceback\n",
      "    value, tb, tb_offset=tb_offset)\n",
      "  File \"C:\\Users\\DELL\\AppData\\Roaming\\Python\\Python37\\site-packages\\IPython\\core\\ultratb.py\", line 1436, in structured_traceback\n",
      "    self, etype, value, tb, tb_offset, number_of_lines_of_context)\n",
      "  File \"C:\\Users\\DELL\\AppData\\Roaming\\Python\\Python37\\site-packages\\IPython\\core\\ultratb.py\", line 1336, in structured_traceback\n",
      "    self, etype, value, tb, tb_offset, number_of_lines_of_context\n",
      "  File \"C:\\Users\\DELL\\AppData\\Roaming\\Python\\Python37\\site-packages\\IPython\\core\\ultratb.py\", line 1211, in structured_traceback\n",
      "    chained_exceptions_tb_offset)\n",
      "  File \"C:\\Users\\DELL\\AppData\\Roaming\\Python\\Python37\\site-packages\\IPython\\core\\ultratb.py\", line 1150, in format_exception_as_a_whole\n",
      "    last_unique, recursion_repeat = find_recursion(orig_etype, evalue, records)\n",
      "  File \"C:\\Users\\DELL\\AppData\\Roaming\\Python\\Python37\\site-packages\\IPython\\core\\ultratb.py\", line 451, in find_recursion\n",
      "    return len(records), 0\n",
      "TypeError: object of type 'NoneType' has no len()\n",
      "\n",
      "During handling of the above exception, another exception occurred:\n",
      "\n",
      "Traceback (most recent call last):\n",
      "  File \"C:\\Users\\DELL\\AppData\\Roaming\\Python\\Python37\\site-packages\\IPython\\core\\interactiveshell.py\", line 2044, in showtraceback\n",
      "    stb = value._render_traceback_()\n",
      "AttributeError: 'TypeError' object has no attribute '_render_traceback_'\n",
      "\n",
      "During handling of the above exception, another exception occurred:\n",
      "\n",
      "Traceback (most recent call last):\n",
      "  File \"C:\\Users\\DELL\\AppData\\Roaming\\Python\\Python37\\site-packages\\IPython\\core\\ultratb.py\", line 1169, in get_records\n",
      "    return _fixed_getinnerframes(etb, number_of_lines_of_context, tb_offset)\n",
      "  File \"C:\\Users\\DELL\\AppData\\Roaming\\Python\\Python37\\site-packages\\IPython\\core\\ultratb.py\", line 316, in wrapped\n",
      "    return f(*args, **kwargs)\n",
      "  File \"C:\\Users\\DELL\\AppData\\Roaming\\Python\\Python37\\site-packages\\IPython\\core\\ultratb.py\", line 350, in _fixed_getinnerframes\n",
      "    records = fix_frame_records_filenames(inspect.getinnerframes(etb, context))\n",
      "  File \"C:\\Users\\DELL\\AppData\\Local\\Programs\\Python\\Python37\\lib\\inspect.py\", line 1502, in getinnerframes\n",
      "    frameinfo = (tb.tb_frame,) + getframeinfo(tb, context)\n",
      "  File \"C:\\Users\\DELL\\AppData\\Local\\Programs\\Python\\Python37\\lib\\inspect.py\", line 1460, in getframeinfo\n",
      "    filename = getsourcefile(frame) or getfile(frame)\n",
      "  File \"C:\\Users\\DELL\\AppData\\Local\\Programs\\Python\\Python37\\lib\\inspect.py\", line 696, in getsourcefile\n",
      "    if getattr(getmodule(object, filename), '__loader__', None) is not None:\n",
      "  File \"C:\\Users\\DELL\\AppData\\Local\\Programs\\Python\\Python37\\lib\\inspect.py\", line 733, in getmodule\n",
      "    if ismodule(module) and hasattr(module, '__file__'):\n",
      "  File \"C:\\Users\\DELL\\AppData\\Local\\Programs\\Python\\Python37\\lib\\site-packages\\tensorflow\\__init__.py\", line 50, in __getattr__\n",
      "    module = self._load()\n",
      "  File \"C:\\Users\\DELL\\AppData\\Local\\Programs\\Python\\Python37\\lib\\site-packages\\tensorflow\\__init__.py\", line 44, in _load\n",
      "    module = _importlib.import_module(self.__name__)\n",
      "  File \"C:\\Users\\DELL\\AppData\\Local\\Programs\\Python\\Python37\\lib\\importlib\\__init__.py\", line 127, in import_module\n",
      "    return _bootstrap._gcd_import(name[level:], package, level)\n",
      "  File \"<frozen importlib._bootstrap>\", line 1006, in _gcd_import\n",
      "  File \"<frozen importlib._bootstrap>\", line 983, in _find_and_load\n",
      "  File \"<frozen importlib._bootstrap>\", line 965, in _find_and_load_unlocked\n",
      "ModuleNotFoundError: No module named 'tensorflow_core.estimator'\n",
      "ERROR! Session/line number was not unique in database. History logging moved to new session 215\n"
     ]
    }
   ],
   "source": [
    "model.fit(X_train, y_train_one_hot, validation_data=(X_test, y_test_one_hot), epochs=5, verbose=1)"
   ]
  },
  {
   "cell_type": "code",
   "execution_count": 16,
   "metadata": {},
   "outputs": [],
   "source": [
    "%store -r extracted_digits"
   ]
  },
  {
   "cell_type": "code",
   "execution_count": 17,
   "metadata": {},
   "outputs": [
    {
     "name": "stdout",
     "output_type": "stream",
     "text": [
      "ERROR! Session/line number was not unique in database. History logging moved to new session 194\n",
      "31 number of cells which are non-empty\n"
     ]
    }
   ],
   "source": [
    "import cv2\n",
    "import numpy as np\n",
    "present = 0\n",
    "from tensorflow.keras.preprocessing.image import img_to_array\n",
    "board = np.zeros((9,9), dtype='int')\n",
    "for i in range(81):\n",
    "    if extracted_digits[i] is not None:\n",
    "        present+=1\n",
    "        value = cv2.resize(extracted_digits[i], (28,28))\n",
    "#         value = value.astype(\"float\") / 255.00\n",
    "        value = img_to_array(value)\n",
    "        value = np.expand_dims(value, axis=0)\n",
    "        prediction = model.predict(value) \n",
    "        board[i // 9][i%9] = np.argmax(prediction)\n",
    "print( present, \"number of cells which are non-empty\")"
   ]
  },
  {
   "cell_type": "code",
   "execution_count": 18,
   "metadata": {},
   "outputs": [
    {
     "name": "stdout",
     "output_type": "stream",
     "text": [
      "0 0 3 1 3 3 0 3 3 \n",
      "\n",
      "3 0 0 0 0 3 0 3 0 \n",
      "\n",
      "0 0 3 0 0 0 3 0 0 \n",
      "\n",
      "0 0 6 2 0 0 0 3 0 \n",
      "\n",
      "6 0 1 0 0 0 3 0 0 \n",
      "\n",
      "0 1 0 0 0 2 3 0 0 \n",
      "\n",
      "0 0 6 0 0 0 3 0 0 \n",
      "\n",
      "0 3 0 6 0 0 0 0 6 \n",
      "\n",
      "6 0 0 3 3 3 6 0 0 \n",
      "\n"
     ]
    }
   ],
   "source": [
    "for i in range(9):\n",
    "    for j in range(9):\n",
    "        print(board[i][j], end = \" \")\n",
    "    print('\\n')"
   ]
  },
  {
   "cell_type": "code",
   "execution_count": null,
   "metadata": {},
   "outputs": [],
   "source": []
  }
 ],
 "metadata": {
  "kernelspec": {
   "display_name": "Python 3.7.9 64-bit",
   "language": "python",
   "name": "python37964bit3b03840a6e2241b6b43fa605f71ad282"
  },
  "language_info": {
   "codemirror_mode": {
    "name": "ipython",
    "version": 3
   },
   "file_extension": ".py",
   "mimetype": "text/x-python",
   "name": "python",
   "nbconvert_exporter": "python",
   "pygments_lexer": "ipython3",
   "version": "3.7.9"
  }
 },
 "nbformat": 4,
 "nbformat_minor": 4
}
